Workbook

Sheet original_data
A1: store_id | B1: month | C1: region | D1: store_type | E1: marketing_spend | F1: footfall | G1: avg_discount_pct | H1: staff_count | I1: inventory_availability_pct | J1: competitor_distance_km | K1: holiday_flag | L1: customer_rating | M1: monthly_sales | N1: monthly_profit
A2: STR-1001 | B2: 45658 | C2: East | D2: Residential | E2: 70389.11 | F2: 8302 | G2: 0.042 | H2: 17 | I2: 75 | J2: 5.28 | K2: 1 | L2: 3.1 | M2: 658832.62 | N2: 84349.93
A3: STR-1001 | B3: 45689 | C3: East | D3: Residential | E3: 43827.89 | F3: 8487 | G3: 0.168 | H3: 23 | I3: 84.4 | J3: 4.31 | K3: 0 | L3: 2.8 | M3: 634436 | N3: 106130.54
A4: STR-1001 | B4: 45717 | C4: East | D4: Residential | E4: 59921.75 | F4: 9113 | G4: 0.133 | H4: 20 | I4: 88 | J4: 12 | K4: 0 | L4: 3.2 | M4: 678722.06 | N4: 101883.86
A5: STR-1001 | B5: 45748 | C5: East | D5: Residential | E5: 56856.63 | F5: 9431 | G5: 0.142 | H5: 23 | I5: 86.9 | J5: 4.97 | K5: 0 | L5: 3.4 | M5: 658920.3 | N5: 97910.37
A6: STR-1002 | B6: 45658 | C6: East | D6: High Street | E6: 48412.64 | F6: 9545 | G6: 0.231 | H6: 21 | I6: 97.6 | J6: 6.94 | K6: 1 | L6: 4.2 | M6: 741341.44 | N6: 119208.17
A7: STR-1002 | B7: 45689 | C7: East | D7: High Street | E7: 64811.21 | F7: 9792 | G7: 0.112 | H7: 20 | I7: 84.2 | J7: 2.88 | K7: 0 | L7: 4.2 | M7: 761835.34 | N7: 149602.23
A8: STR-1002 | B8: 45717 | C8: East | D8: High Street | E8: 46213.45 | F8: 10616 | G8: 0.122 | H8: 22 | I8: 85.2 | J8: 0.2 | K8: 1 | L8: 4.1 | M8: 806615.54 | N8: 131364.62
A9: STR-1002 | B9: 45748 | C9: East | D9: High Street | E9: 68148.52 | F9: 8567 | G9: 0.127 | H9: 23 | I9: 95.6 | J9: 0.8 | K9: 0 | L9: 3.9 | M9: 850164.26 | N9: 149262.75
A10: STR-1003 | B10: 45658 | C10: North | D10: Airport | E10: 71838.86 | F10: 10979 | G10: 0.215 | H10: 26 | I10: 88.6 | J10: 7.7 | K10: 1 | L10: 3.8 | M10: 930581.7 | N10: 136207.98
A11: STR-1003 | B11: 45689 | C11: North | D11: Airport | E11: 68133.44 | F11: 9459 | G11: 0.22 | H11: 21 | I11: 85 | J11: 1.91 | K11: 0 | L11: 4.2 | M11: 779010.94 | N11: 106328.09
A12: STR-1003 | B12: 45717 | C12: North | D12: Airport | E12: 34285.21 | F12: 9172 | G12: 0.213 | H12: 22 | I12: 88.3 | J12: 10.46 | K12: 1 | L12: 3.8 | M12: 723060.76 | N12: 123131.24
A13: STR-1003 | B13: 45748 | C13: North | D13: Airport | E13: 67979.88 | F13: 11230 | G13: 0.002 | H13: 28 | I13: 85.3 | J13: 7.16 | K13: 0 | L13: 3.8 | M13: 910791.94 | N13: 158891.28
... A34: STR-1009 | B34: 45658 | C34: North | D34: Residential | E34: 54597.83 | F34: 9429 | G34: 0.188 | H34: 21 | I34: 83.3 | J34: 11.71 | K34: 0 | L34: 4.2 | M34: 641865.03 | N34: 81342.58
A35: STR-1009 | B35: 45689 | C35: North | D35: Residential | E35: 73771.91 | F35: 11695 | G35: 0.07 | H35: 25 | I35: 84.7 | J35: 0.62 | K35: 0 | M35: 799477.76 | N35: 164974.41
A36: STR-1009 | B36: 45717 | C36: North | D36: Residential | E36: 74413.88 | F36: 9449 | G36: 0.039 | H36: 23 | I36: 92.1 | J36: 2.12 | K36: 0 | L36: 3.5 | M36: 798952.17 | N36: 161499.04
A37: STR-1009 | B37: 45748 | C37: North | D37: Residential | E37: 52483.77 | F37: 10453 | G37: 0.247 | H37: 25 | I37: 99 | J37: 6.31 | K37: 0 | L37: 3.6 | M37: 800979.78 | N37: 149242.27
A38: STR-1010 | B38: 45658 | C38: North | D38: Mall | E38: 75269.87 | F38: 8838 | G38: 0.092 | H38: 21 | I38: 83.1 | J38: 9.56 | K38: 1 | L38: 4.2 | M38: 820593.93 | N38: 115860.06
A39: STR-1010 | B39: 45689 | C39: North | D39: Mall | E39: 61245.41 | F39: 8156 | G39: 0.156 | H39: 19 | I39: 92.9 | J39: 9.05 | K39: 0 | L39: 3.8 | M39: 718330.53 | N39: 93247.9
A40: STR-1010 | B40: 45717 | C40: North | D40: Mall | E40: 93381.26 | F40: 7562 | G40: 0.198 | H40: 19 | I40: 82.9 | J40: 5.05 | K40: 0 | L40: 4 | M40: 736633.4 | N40: 115654.66
A41: STR-1010 | B41: 45748 | C41: North | D41: Mall | E41: 65012.19 | F41: 9598 | G41: 0.085 | H41: 24 | I41: 98.3 | J41: 0.89 | K41: 0 | L41: 3.8 | M41: 828623.85 | N41: 167320.52
A42: STR-1011 | B42: 45658 | C42: East | D42: Mall | E42: 40462.94 | F42: 3660 | G42: 0.218 | H42: 11 | I42: 95.2 | J42: 5.57 | K42: 0 | L42: 4.4 | M42: 592195.85 | N42: 92291.56
A43: STR-1011 | B43: 45689 | C43: East | D43: Mall | E43: 46123.88 | F43: 3227 | G43: 0.143 | H43: 10 | I43: 75.4 | J43: 1.06 | K43: 0 | L43: 4.4 | M43: 532644.46 | N43: 60681.32
A44: STR-1011 | B44: 45717 | C44: East | D44: Mall | E44: 68077.54 | F44: 3360 | G44: 0.128 | H44: 14 | I44: 88.2 | J44: 1.24 | K44: 1 | L44: 4 | M44: 657429.18 | N44: 88919.74
A45: STR-1011 | B45: 45748 | C45: East | D45: Mall | E45: 64882.14 | F45: 3642 | G45: 0.019 | H45: 13 | I45: 87.8 | J45: 4.52 | K45: 0 | L45: 4.2 | M45: 605178 | N45: 106958.74
A46: STR-1012 | B46: 45658 | C46: West | D46: Residential | E46: 138855.51 | F46: 5145 | G46: 0.06 | H46: 17 | I46: 88.2 | J46: 9.58 | K46: 0 | L46: 3.2 | M46: 595467.6 | N46: 104276.46
A47: STR-1012 | B47: 45689 | C47: West | D47: Residential | E47: 63630.21 | F47: 4460 | G47: 0.235 | H47: 14 | I47: 98.6 | J47: 5.52 | K47: 0 | L47: 3.5 | M47: 599603.4 | N47: 112685.12
... A72: STR-1018 | B72: 45717 | C72: East | D72: High Street | E72: 60571.82 | F72: 3193 | G72: 0.197 | H72: 7 | I72: 99 | J72: 1.43 | K72: 0 | L72: 3.2 | M72: 605023.87 | N72: 98545.81
A73: STR-1018 | B73: 45748 | C73: East | D73: High Street | E73: 55081.16 | F73: 5485 | G73: 0.036 | H73: 12 | I73: 88 | K73: 0 | L73: 3.5 | M73: 674774.09 | N73: 141917.59
A74: STR-1019 | B74: 45658 | C74: East | D74: Residential | E74: 46201.46 | F74: 5918 | G74: 0.277 | H74: 13 | I74: 78.8 | J74: 4.91 | K74: 0 | L74: 4.5 | M74: 616069.41 | N74: 54453.99
A75: STR-1019 | B75: 45689 | C75: East | D75: Residential | E75: 53762.92 | F75: 6821 | G75: 0.066 | H75: 19 | I75: 94.6 | J75: 7.03 | K75: 0 | L75: 4.4 | M75: 630829.94 | N75: 117090.02
A76: STR-1019 | B76: 45717 | C76: East | D76: Residential | E76: 70144.78 | F76: 6806 | G76: 0.178 | H76: 20 | I76: 93.1 | J76: 0.28 | K76: 1 | L76: 4.3 | M76: 788087.68 | N76: 116803.42
A77: STR-1019 | B77: 45748 | C77: East | D77: Residential | E77: 58749.63 | F77: 8252 | G77: 0.203 | H77: 20 | I77: 85.2 | J77: 3.61 | K77: 0 | L77: 4.5 | M77: 680840.36 | N77: 68007.68
A78: STR-1020 | B78: 45658 | C78: South | D78: High Street | E78: 56973.18 | F78: 6662 | G78: 0.1 | H78: 15 | I78: 77.7 | J78: 7.52 | K78: 1 | L78: 3.2 | M78: 643657.47 | N78: 87022.45
A79: STR-1020 | B79: 45689 | C79: South | D79: High Street | E79: 54872.82 | F79: 5962 | G79: 0.064 | H79: 12 | I79: 85.4 | J79: 2.58 | K79: 0 | L79: 2.9 | M79: 691112.6 | N79: 109212.83
A80: STR-1020 | B80: 45717 | C80: South | D80: High Street | E80: 80562.81 | F80: 7470 | G80: 0.172 | H80: 16 | I80: 83.5 | J80: 2.29 | K80: 0 | L80: 3.3 | M80: 776922.17 | N80: 150701.93
A81: STR-1020 | B81: 45748 | C81: South | D81: High Street | E81: 77999.9 | F81: 5974 | G81: 0.252 | H81: 14 | I81: 81.3 | J81: 2.39 | K81: 0 | L81: 3.2 | M81: 636561.34 | N81: 93861.06
A82: STR-1021 | B82: 45658 | C82: West | D82: Mall | E82: 60881.01 | F82: 5410 | G82: 0.179 | H82: 15 | I82: 83.9 | J82: 5.24 | K82: 0 | L82: 4.6 | M82: 621369.58 | N82: 85493.64
A83: STR-1021 | B83: 45689 | C83: West | D83: Mall | E83: 60628.38 | F83: 4451 | G83: 0.095 | H83: 10 | I83: 89.6 | J83: 3.17 | K83: 0 | L83: 4.6 | M83: 682208.01 | N83: 110318.84
A84: STR-1021 | B84: 45717 | C84: West | D84: Mall | E84: 72731.14 | F84: 4644 | G84: 0.084 | H84: 15 | I84: 87.1 | J84: 2.66 | K84: 0 | L84: 4.6 | M84: 727241.86 | N84: 155810.3
...

Sheet cleaned_data
A1: store_id | B1: month | C1: region | D1: store_type | E1: marketing_spend | F1: footfall | G1: avg_discount_pct | H1: staff_count | I1: inventory_availability_pct | J1: competitor_distance_km | K1: holiday_flag | L1: customer_rating | M1: monthly_sales | N1: monthly_profit
A2: STR-1001 | B2: 45658 | C2: East | D2: Residential | E2: 70389.11 | F2: 8302 | G2: 0.042 | H2: 17 | I2: 75 | J2: 5.28 | K2: 1 | L2: 3.1 | M2: 658832.62 | N2: 84349.93
A3: STR-1001 | B3: 45689 | C3: East | D3: Residential | E3: 43827.89 | F3: 8487 | G3: 0.168 | H3: 23 | I3: 84.4 | J3: 4.31 | K3: 0 | L3: 2.8 | M3: 634436 | N3: 106130.54
A4: STR-1001 | B4: 45717 | C4: East | D4: Residential | E4: 59921.75 | F4: 9113 | G4: 0.133 | H4: 20 | I4: 88 | J4: 12 | K4: 0 | L4: 3.2 | M4: 678722.06 | N4: 101883.86
A5: STR-1001 | B5: 45748 | C5: East | D5: Residential | E5: 56856.63 | F5: 9431 | G5: 0.142 | H5: 23 | I5: 86.9 | J5: 4.97 | K5: 0 | L5: 3.4 | M5: 658920.3 | N5: 97910.37
A6: STR-1002 | B6: 45658 | C6: East | D6: High Street | E6: 48412.64 | F6: 9545 | G6: 0.231 | H6: 21 | I6: 97.6 | J6: 6.94 | K6: 1 | L6: 4.2 | M6: 741341.44 | N6: 119208.17
A7: STR-1002 | B7: 45689 | C7: East | D7: High Street | E7: 64811.21 | F7: 9792 | G7: 0.112 | H7: 20 | I7: 84.2 | J7: 2.88 | K7: 0 | L7: 4.2 | M7: 761835.34 | N7: 149602.23
A8: STR-1002 | B8: 45717 | C8: East | D8: High Street | E8: 46213.45 | F8: 10616 | G8: 0.122 | H8: 22 | I8: 85.2 | J8: 0.2 | K8: 1 | L8: 4.1 | M8: 806615.54 | N8: 131364.62
A9: STR-1002 | B9: 45748 | C9: East | D9: High Street | E9: 68148.52 | F9: 8567 | G9: 0.127 | H9: 23 | I9: 95.6 | J9: 0.8 | K9: 0 | L9: 3.9 | M9: 850164.26 | N9: 149262.75
A10: STR-1003 | B10: 45658 | C10: North | D10: Airport | E10: 71838.86 | F10: 10979 | G10: 0.215 | H10: 26 | I10: 88.6 | J10: 7.7 | K10: 1 | L10: 3.8 | M10: 930581.7 | N10: 136207.98
A11: STR-1003 | B11: 45689 | C11: North | D11: Airport | E11: 68133.44 | F11: 9459 | G11: 0.22 | H11: 21 | I11: 85 | J11: 1.91 | K11: 0 | L11: 4.2 | M11: 779010.94 | N11: 106328.09
A12: STR-1003 | B12: 45717 | C12: North | D12: Airport | E12: 34285.21 | F12: 9172 | G12: 0.213 | H12: 22 | I12: 88.3 | J12: 10.46 | K12: 1 | L12: 3.8 | M12: 723060.76 | N12: 123131.24
A13: STR-1003 | B13: 45748 | C13: North | D13: Airport | E13: 67979.88 | F13: 11230 | G13: 0.002 | H13: 28 | I13: 85.3 | J13: 7.16 | K13: 0 | L13: 3.8 | M13: 910791.94 | N13: 158891.28
... A34: STR-1009 | B34: 45658 | C34: North | D34: Residential | E34: 54597.83 | F34: 9429 | G34: 0.188 | H34: 21 | I34: 83.3 | J34: 11.71 | K34: 0 | L34: 4.2 | M34: 641865.03 | N34: 81342.58
A35: STR-1009 | B35: 45689 | C35: North | D35: Residential | E35: 73771.91 | F35: 11695 | G35: 0.07 | H35: 25 | I35: 84.7 | J35: 0.62 | K35: 0 | M35: 799477.76 | N35: 164974.41
A36: STR-1009 | B36: 45717 | C36: North | D36: Residential | E36: 74413.88 | F36: 9449 | G36: 0.039 | H36: 23 | I36: 92.1 | J36: 2.12 | K36: 0 | L36: 3.5 | M36: 798952.17 | N36: 161499.04
A37: STR-1009 | B37: 45748 | C37: North | D37: Residential | E37: 52483.77 | F37: 10453 | G37: 0.247 | H37: 25 | I37: 99 | J37: 6.31 | K37: 0 | L37: 3.6 | M37: 800979.78 | N37: 149242.27
A38: STR-1010 | B38: 45658 | C38: North | D38: Mall | E38: 75269.87 | F38: 8838 | G38: 0.092 | H38: 21 | I38: 83.1 | J38: 9.56 | K38: 1 | L38: 4.2 | M38: 820593.93 | N38: 115860.06
A39: STR-1010 | B39: 45689 | C39: North | D39: Mall | E39: 61245.41 | F39: 8156 | G39: 0.156 | H39: 19 | I39: 92.9 | J39: 9.05 | K39: 0 | L39: 3.8 | M39: 718330.53 | N39: 93247.9
A40: STR-1010 | B40: 45717 | C40: North | D40: Mall | E40: 93381.26 | F40: 7562 | G40: 0.198 | H40: 19 | I40: 82.9 | J40: 5.05 | K40: 0 | L40: 4 | M40: 736633.4 | N40: 115654.66
A41: STR-1010 | B41: 45748 | C41: North | D41: Mall | E41: 65012.19 | F41: 9598 | G41: 0.085 | H41: 24 | I41: 98.3 | J41: 0.89 | K41: 0 | L41: 3.8 | M41: 828623.85 | N41: 167320.52
A42: STR-1011 | B42: 45658 | C42: East | D42: Mall | E42: 40462.94 | F42: 3660 | G42: 0.218 | H42: 11 | I42: 95.2 | J42: 5.57 | K42: 0 | L42: 4.4 | M42: 592195.85 | N42: 92291.56
A43: STR-1011 | B43: 45689 | C43: East | D43: Mall | E43: 46123.88 | F43: 3227 | G43: 0.143 | H43: 10 | I43: 75.4 | J43: 1.06 | K43: 0 | L43: 4.4 | M43: 532644.46 | N43: 60681.32
A44: STR-1011 | B44: 45717 | C44: East | D44: Mall | E44: 68077.54 | F44: 3360 | G44: 0.128 | H44: 14 | I44: 88.2 | J44: 1.24 | K44: 1 | L44: 4 | M44: 657429.18 | N44: 88919.74
A45: STR-1011 | B45: 45748 | C45: East | D45: Mall | E45: 64882.14 | F45: 3642 | G45: 0.019 | H45: 13 | I45: 87.8 | J45: 4.52 | K45: 0 | L45: 4.2 | M45: 605178 | N45: 106958.74
A46: STR-1012 | B46: 45658 | C46: West | D46: Residential | E46: 138855.51 | F46: 5145 | G46: 0.06 | H46: 17 | I46: 88.2 | J46: 9.58 | K46: 0 | L46: 3.2 | M46: 595467.6 | N46: 104276.46
A47: STR-1012 | B47: 45689 | C47: West | D47: Residential | E47: 63630.21 | F47: 4460 | G47: 0.235 | H47: 14 | I47: 98.6 | J47: 5.52 | K47: 0 | L47: 3.5 | M47: 599603.4 | N47: 112685.12
... A72: STR-1018 | B72: 45717 | C72: East | D72: High Street | E72: 60571.82 | F72: 3193 | G72: 0.197 | H72: 7 | I72: 99 | J72: 1.43 | K72: 0 | L72: 3.2 | M72: 605023.87 | N72: 98545.81
A73: STR-1018 | B73: 45748 | C73: East | D73: High Street | E73: 55081.16 | F73: 5485 | G73: 0.036 | H73: 12 | I73: 88 | K73: 0 | L73: 3.5 | M73: 674774.09 | N73: 141917.59
A74: STR-1019 | B74: 45658 | C74: East | D74: Residential | E74: 46201.46 | F74: 5918 | G74: 0.277 | H74: 13 | I74: 78.8 | J74: 4.91 | K74: 0 | L74: 4.5 | M74: 616069.41 | N74: 54453.99
A75: STR-1019 | B75: 45689 | C75: East | D75: Residential | E75: 53762.92 | F75: 6821 | G75: 0.066 | H75: 19 | I75: 94.6 | J75: 7.03 | K75: 0 | L75: 4.4 | M75: 630829.94 | N75: 117090.02
A76: STR-1019 | B76: 45717 | C76: East | D76: Residential | E76: 70144.78 | F76: 6806 | G76: 0.178 | H76: 20 | I76: 93.1 | J76: 0.28 | K76: 1 | L76: 4.3 | M76: 788087.68 | N76: 116803.42
A77: STR-1019 | B77: 45748 | C77: East | D77: Residential | E77: 58749.63 | F77: 8252 | G77: 0.203 | H77: 20 | I77: 85.2 | J77: 3.61 | K77: 0 | L77: 4.5 | M77: 680840.36 | N77: 68007.68
A78: STR-1020 | B78: 45658 | C78: South | D78: High Street | E78: 56973.18 | F78: 6662 | G78: 0.1 | H78: 15 | I78: 77.7 | J78: 7.52 | K78: 1 | L78: 3.2 | M78: 643657.47 | N78: 87022.45
A79: STR-1020 | B79: 45689 | C79: South | D79: High Street | E79: 54872.82 | F79: 5962 | G79: 0.064 | H79: 12 | I79: 85.4 | J79: 2.58 | K79: 0 | L79: 2.9 | M79: 691112.6 | N79: 109212.83
A80: STR-1020 | B80: 45717 | C80: South | D80: High Street | E80: 80562.81 | F80: 7470 | G80: 0.172 | H80: 16 | I80: 83.5 | J80: 2.29 | K80: 0 | L80: 3.3 | M80: 776922.17 | N80: 150701.93
A81: STR-1020 | B81: 45748 | C81: South | D81: High Street | E81: 77999.9 | F81: 5974 | G81: 0.252 | H81: 14 | I81: 81.3 | J81: 2.39 | K81: 0 | L81: 3.2 | M81: 636561.34 | N81: 93861.06
A82: STR-1021 | B82: 45658 | C82: West | D82: Mall | E82: 60881.01 | F82: 5410 | G82: 0.179 | H82: 15 | I82: 83.9 | J82: 5.24 | K82: 0 | L82: 4.6 | M82: 621369.58 | N82: 85493.64
A83: STR-1021 | B83: 45689 | C83: West | D83: Mall | E83: 60628.38 | F83: 4451 | G83: 0.095 | H83: 10 | I83: 89.6 | J83: 3.17 | K83: 0 | L83: 4.6 | M83: 682208.01 | N83: 110318.84
A84: STR-1021 | B84: 45717 | C84: West | D84: Mall | E84: 72731.14 | F84: 4644 | G84: 0.084 | H84: 15 | I84: 87.1 | J84: 2.66 | K84: 0 | L84: 4.6 | M84: 727241.86 | N84: 155810.3
...

Sheet dummy_variables
A1: Dummy Variable Creation
A2: store_type (reference category = "High Street") and region (reference category = "East") are converted to 0/1 dummy columns. Reference categories are dropped to avoid the dummy-variable trap (perfect multicollinearity if all categories are included alongside an intercept).
A4: store_id | B4: month | C4: store_type | D4: region | E4: store_type_Mall | F4: store_type_Residential | G4: store_type_Airport | H4: region_North | I4: region_South | J4: region_West
A5: =cleaned_data!A2 -> STR-1001 | B5: =cleaned_data!B2 -> 45658 | C5: =cleaned_data!D2 -> Residential | D5: =cleaned_data!C2 -> East | E5: =IF(cleaned_data!D2="Mall",1,0) -> 0 | F5: =IF(cleaned_data!D2="Residential",1,0) -> 1 | G5: =IF(cleaned_data!D2="Airport",1,0) -> 0 | H5: =IF(cleaned_data!C2="North",1,0) -> 0 | I5: =IF(cleaned_data!C2="South",1,0) -> 0 | J5: =IF(cleaned_data!C2="West",1,0) -> 0
A6: =cleaned_data!A3 -> STR-1001 | B6: =cleaned_data!B3 -> 45689 | C6: =cleaned_data!D3 -> Residential | D6: =cleaned_data!C3 -> East | E6: =IF(cleaned_data!D3="Mall",1,0) -> 0 | F6: =IF(cleaned_data!D3="Residential",1,0) -> 1 | G6: =IF(cleaned_data!D3="Airport",1,0) -> 0 | H6: =IF(cleaned_data!C3="North",1,0) -> 0 | I6: =IF(cleaned_data!C3="South",1,0) -> 0 | J6: =IF(cleaned_data!C3="West",1,0) -> 0
A7: =cleaned_data!A4 -> STR-1001 | B7: =cleaned_data!B4 -> 45717 | C7: =cleaned_data!D4 -> Residential | D7: =cleaned_data!C4 -> East | E7: =IF(cleaned_data!D4="Mall",1,0) -> 0 | F7: =IF(cleaned_data!D4="Residential",1,0) -> 1 | G7: =IF(cleaned_data!D4="Airport",1,0) -> 0 | H7: =IF(cleaned_data!C4="North",1,0) -> 0 | I7: =IF(cleaned_data!C4="South",1,0) -> 0 | J7: =IF(cleaned_data!C4="West",1,0) -> 0
A8: =cleaned_data!A5 -> STR-1001 | B8: =cleaned_data!B5 -> 45748 | C8: =cleaned_data!D5 -> Residential | D8: =cleaned_data!C5 -> East | E8: =IF(cleaned_data!D5="Mall",1,0) -> 0 | F8: =IF(cleaned_data!D5="Residential",1,0) -> 1 | G8: =IF(cleaned_data!D5="Airport",1,0) -> 0 | H8: =IF(cleaned_data!C5="North",1,0) -> 0 | I8: =IF(cleaned_data!C5="South",1,0) -> 0 | J8: =IF(cleaned_data!C5="West",1,0) -> 0
A9: =cleaned_data!A6 -> STR-1002 | B9: =cleaned_data!B6 -> 45658 | C9: =cleaned_data!D6 -> High Street | D9: =cleaned_data!C6 -> East | E9: =IF(cleaned_data!D6="Mall",1,0) -> 0 | F9: =IF(cleaned_data!D6="Residential",1,0) -> 0 | G9: =IF(cleaned_data!D6="Airport",1,0) -> 0 | H9: =IF(cleaned_data!C6="North",1,0) -> 0 | I9: =IF(cleaned_data!C6="South",1,0) -> 0 | J9: =IF(cleaned_data!C6="West",1,0) -> 0
A10: =cleaned_data!A7 -> STR-1002 | B10: =cleaned_data!B7 -> 45689 | C10: =cleaned_data!D7 -> High Street | D10: =cleaned_data!C7 -> East | E10: =IF(cleaned_data!D7="Mall",1,0) -> 0 | F10: =IF(cleaned_data!D7="Residential",1,0) -> 0 | G10: =IF(cleaned_data!D7="Airport",1,0) -> 0 | H10: =IF(cleaned_data!C7="North",1,0) -> 0 | I10: =IF(cleaned_data!C7="South",1,0) -> 0 | J10: =IF(cleaned_data!C7="West",1,0) -> 0
A11: =cleaned_data!A8 -> STR-1002 | B11: =cleaned_data!B8 -> 45717 | C11: =cleaned_data!D8 -> High Street | D11: =cleaned_data!C8 -> East | E11: =IF(cleaned_data!D8="Mall",1,0) -> 0 | F11: =IF(cleaned_data!D8="Residential",1,0) -> 0 | G11: =IF(cleaned_data!D8="Airport",1,0) -> 0 | H11: =IF(cleaned_data!C8="North",1,0) -> 0 | I11: =IF(cleaned_data!C8="South",1,0) -> 0 | J11: =IF(cleaned_data!C8="West",1,0) -> 0
A12: =cleaned_data!A9 -> STR-1002 | B12: =cleaned_data!B9 -> 45748 | C12: =cleaned_data!D9 -> High Street | D12: =cleaned_data!C9 -> East | E12: =IF(cleaned_data!D9="Mall",1,0) -> 0 | F12: =IF(cleaned_data!D9="Residential",1,0) -> 0 | G12: =IF(cleaned_data!D9="Airport",1,0) -> 0 | H12: =IF(cleaned_data!C9="North",1,0) -> 0 | I12: =IF(cleaned_data!C9="South",1,0) -> 0 | J12: =IF(cleaned_data!C9="West",1,0) -> 0
A13: =cleaned_data!A10 -> STR-1003 | B13: =cleaned_data!B10 -> 45658 | C13: =cleaned_data!D10 -> Airport | D13: =cleaned_data!C10 -> North | E13: =IF(cleaned_data!D10="Mall",1,0) -> 0 | F13: =IF(cleaned_data!D10="Residential",1,0) -> 0 | G13: =IF(cleaned_data!D10="Airport",1,0) -> 1 | H13: =IF(cleaned_data!C10="North",1,0) -> 1 | I13: =IF(cleaned_data!C10="South",1,0) -> 0 | J13: =IF(cleaned_data!C10="West",1,0) -> 0
A14: =cleaned_data!A11 -> STR-1003 | B14: =cleaned_data!B11 -> 45689 | C14: =cleaned_data!D11 -> Airport | D14: =cleaned_data!C11 -> North | E14: =IF(cleaned_data!D11="Mall",1,0) -> 0 | F14: =IF(cleaned_data!D11="Residential",1,0) -> 0 | G14: =IF(cleaned_data!D11="Airport",1,0) -> 1 | H14: =IF(cleaned_data!C11="North",1,0) -> 1 | I14: =IF(cleaned_data!C11="South",1,0) -> 0 | J14: =IF(cleaned_data!C11="West",1,0) -> 0
A15: =cleaned_data!A12 -> STR-1003 | B15: =cleaned_data!B12 -> 45717 | C15: =cleaned_data!D12 -> Airport | D15: =cleaned_data!C12 -> North | E15: =IF(cleaned_data!D12="Mall",1,0) -> 0 | F15: =IF(cleaned_data!D12="Residential",1,0) -> 0 | G15: =IF(cleaned_data!D12="Airport",1,0) -> 1 | H15: =IF(cleaned_data!C12="North",1,0) -> 1 | I15: =IF(cleaned_data!C12="South",1,0) -> 0 | J15: =IF(cleaned_data!C12="West",1,0) -> 0
A16: =cleaned_data!A13 -> STR-1003 | B16: =cleaned_data!B13 -> 45748 | C16: =cleaned_data!D13 -> Airport | D16: =cleaned_data!C13 -> North | E16: =IF(cleaned_data!D13="Mall",1,0) -> 0 | F16: =IF(cleaned_data!D13="Residential",1,0) -> 0 | G16: =IF(cleaned_data!D13="Airport",1,0) -> 1 | H16: =IF(cleaned_data!C13="North",1,0) -> 1 | I16: =IF(cleaned_data!C13="South",1,0) -> 0 | J16: =IF(cleaned_data!C13="West",1,0) -> 0
... A324: =cleaned_data!A321 -> STR-1080 | B324: =cleaned_data!B321 -> 45748 | C324: =cleaned_data!D321 -> Residential | D324: =cleaned_data!C321 -> East | E324: =IF(cleaned_data!D321="Mall",1,0) -> 0 | F324: =IF(cleaned_data!D321="Residential",1,0) -> 1 | G324: =IF(cleaned_data!D321="Airport",1,0) -> 0 | H324: =IF(cleaned_data!C321="North",1,0) -> 0 | I324: =IF(cleaned_data!C321="South",1,0) -> 0 | J324: =IF(cleaned_data!C321="West",1,0) -> 0

Sheet simple_regression
A1: Simple Linear Regression Models (monthly_sales as dependent variable)
A3: Model A: monthly_sales ~ marketing_spend
A4: Statistic | B4: Value | E4: Notes
A5: Slope (coefficient) | B5: =SLOPE(cleaned_data!M2:M321,cleaned_data!E2:E321) -> 2.1295753 | E5: Change in monthly_sales per 1-unit increase in marketing_spend
A6: Intercept | B6: =INTERCEPT(cleaned_data!M2:M321,cleaned_data!E2:E321) -> 560777.35 | E6: Predicted monthly_sales when the independent variable is 0
A7: R-squared | B7: =RSQ(cleaned_data!M2:M321,cleaned_data!E2:E321) -> 0.16724469 | E7: Share of variance in monthly_sales explained by this variable alone
A8: N (observations) | B8: =COUNT(cleaned_data!E2:E321) -> 320
A9: Standard error of slope | B9: =STEYX(cleaned_data!M2:M321,cleaned_data!E2:E321)/SQRT(DEVSQ(cleaned_data!E2:E321)) -> 0.26647838
A10: t-statistic | B10: =B5/B9 -> 7.9915501
A11: P-value (two-tailed) | B11: =_xlfn.T.DIST.2T(ABS(B10),B8-2) -> 2.4800615e-14
A12: Regression equation | B12: ="monthly_sales = "&TEXT(B6,"0.00")&" + "&TEXT(B5,"0.0000")&" * marketing_spend" -> monthly_sales = 560777.35 + 2.1296 * marketing_spend
A14: Model B: monthly_sales ~ footfall
A15: Statistic | B15: Value | E15: Notes
A16: Slope (coefficient) | B16: =SLOPE(cleaned_data!M2:M321,cleaned_data!F2:F321) -> 35.678031 | E16: Change in monthly_sales per 1-unit increase in footfall
A17: Intercept | B17: =INTERCEPT(cleaned_data!M2:M321,cleaned_data!F2:F321) -> 446410.58 | E17: Predicted monthly_sales when the independent variable is 0
A18: R-squared | B18: =RSQ(cleaned_data!M2:M321,cleaned_data!F2:F321) -> 0.73628534 | E18: Share of variance in monthly_sales explained by this variable alone
A19: N (observations) | B19: =COUNT(cleaned_data!F2:F321) -> 320
A20: Standard error of slope | B20: =STEYX(cleaned_data!M2:M321,cleaned_data!F2:F321)/SQRT(DEVSQ(cleaned_data!F2:F321)) -> 1.1973783
A21: t-statistic | B21: =B16/B20 -> 29.796791
A22: P-value (two-tailed) | B22: =_xlfn.T.DIST.2T(ABS(B21),B19-2) -> 4.7503615e-94
A23: Regression equation | B23: ="monthly_sales = "&TEXT(B17,"0.00")&" + "&TEXT(B16,"0.0000")&" * footfall" -> monthly_sales = 446410.58 + 35.6780 * footfall
A25: Model C: monthly_sales ~ inventory_availability_pct
A26: Statistic | B26: Value | E26: Notes
A27: Slope (coefficient) | B27: =SLOPE(cleaned_data!M2:M321,cleaned_data!I2:I321) -> 2217.8319 | E27: Change in monthly_sales per 1-unit increase in inventory_availability_pct
A28: Intercept | B28: =INTERCEPT(cleaned_data!M2:M321,cleaned_data!I2:I321) -> 484814.26 | E28: Predicted monthly_sales when the independent variable is 0
A29: R-squared | B29: =RSQ(cleaned_data!M2:M321,cleaned_data!I2:I321) -> 0.013115016 | E29: Share of variance in monthly_sales explained by this variable alone
A30: N (observations) | B30: =COUNT(cleaned_data!I2:I321) -> 320
A31: Standard error of slope | B31: =STEYX(cleaned_data!M2:M321,cleaned_data!I2:I321)/SQRT(DEVSQ(cleaned_data!I2:I321)) -> 1078.8571
A32: t-statistic | B32: =B27/B31 -> 2.0557235
A33: P-value (two-tailed) | B33: =_xlfn.T.DIST.2T(ABS(B32),B30-2) -> 0.040625297
A34: Regression equation | B34: ="monthly_sales = "&TEXT(B28,"0.00")&" + "&TEXT(B27,"0.0000")&" * inventory_availability_pct" -> monthly_sales = 484814.26 + 2217.8319 * inventory_availability_pct

Sheet multiple_regression
A1: Multiple Regression Model: monthly_sales ~ all predictors (with dummy variables)
A3: Reference categories (omitted to avoid the dummy-variable trap): store_type = "High Street", region = "East". All dummy coefficients are interpreted relative to these reference groups.
A5: Predictor matrix (materialized for LINEST; mirrors cleaned_data / dummy_variables)
A6: row# | B6: footfall | C6: marketing_spend | D6: staff_count | E6: inventory_availability_pct | F6: avg_discount_pct | G6: holiday_flag | H6: store_type_Mall | I6: store_type_Residential | J6: store_type_Airport | K6: region_North | L6: region_South | M6: region_West
A7: 1 | B7: =cleaned_data!F2 -> 8302 | C7: =cleaned_data!E2 -> 70389.11 | D7: =cleaned_data!H2 -> 17 | E7: =cleaned_data!I2 -> 75 | F7: =cleaned_data!G2 -> 0.042 | G7: =cleaned_data!K2 -> 1 | H7: =dummy_variables!E5 -> 0 | I7: =dummy_variables!F5 -> 1 | J7: =dummy_variables!G5 -> 0 | K7: =dummy_variables!H5 -> 0 | L7: =dummy_variables!I5 -> 0 | M7: =dummy_variables!J5 -> 0
A8: 2 | B8: =cleaned_data!F3 -> 8487 | C8: =cleaned_data!E3 -> 43827.89 | D8: =cleaned_data!H3 -> 23 | E8: =cleaned_data!I3 -> 84.4 | F8: =cleaned_data!G3 -> 0.168 | G8: =cleaned_data!K3 -> 0 | H8: =dummy_variables!E6 -> 0 | I8: =dummy_variables!F6 -> 1 | J8: =dummy_variables!G6 -> 0 | K8: =dummy_variables!H6 -> 0 | L8: =dummy_variables!I6 -> 0 | M8: =dummy_variables!J6 -> 0
A9: 3 | B9: =cleaned_data!F4 -> 9113 | C9: =cleaned_data!E4 -> 59921.75 | D9: =cleaned_data!H4 -> 20 | E9: =cleaned_data!I4 -> 88 | F9: =cleaned_data!G4 -> 0.133 | G9: =cleaned_data!K4 -> 0 | H9: =dummy_variables!E7 -> 0 | I9: =dummy_variables!F7 -> 1 | J9: =dummy_variables!G7 -> 0 | K9: =dummy_variables!H7 -> 0 | L9: =dummy_variables!I7 -> 0 | M9: =dummy_variables!J7 -> 0
A10: 4 | B10: =cleaned_data!F5 -> 9431 | C10: =cleaned_data!E5 -> 56856.63 | D10: =cleaned_data!H5 -> 23 | E10: =cleaned_data!I5 -> 86.9 | F10: =cleaned_data!G5 -> 0.142 | G10: =cleaned_data!K5 -> 0 | H10: =dummy_variables!E8 -> 0 | I10: =dummy_variables!F8 -> 1 | J10: =dummy_variables!G8 -> 0 | K10: =dummy_variables!H8 -> 0 | L10: =dummy_variables!I8 -> 0 | M10: =dummy_variables!J8 -> 0
A11: 5 | B11: =cleaned_data!F6 -> 9545 | C11: =cleaned_data!E6 -> 48412.64 | D11: =cleaned_data!H6 -> 21 | E11: =cleaned_data!I6 -> 97.6 | F11: =cleaned_data!G6 -> 0.231 | G11: =cleaned_data!K6 -> 1 | H11: =dummy_variables!E9 -> 0 | I11: =dummy_variables!F9 -> 0 | J11: =dummy_variables!G9 -> 0 | K11: =dummy_variables!H9 -> 0 | L11: =dummy_variables!I9 -> 0 | M11: =dummy_variables!J9 -> 0
A12: 6 | B12: =cleaned_data!F7 -> 9792 | C12: =cleaned_data!E7 -> 64811.21 | D12: =cleaned_data!H7 -> 20 | E12: =cleaned_data!I7 -> 84.2 | F12: =cleaned_data!G7 -> 0.112 | G12: =cleaned_data!K7 -> 0 | H12: =dummy_variables!E10 -> 0 | I12: =dummy_variables!F10 -> 0 | J12: =dummy_variables!G10 -> 0 | K12: =dummy_variables!H10 -> 0 | L12: =dummy_variables!I10 -> 0 | M12: =dummy_variables!J10 -> 0
A13: 7 | B13: =cleaned_data!F8 -> 10616 | C13: =cleaned_data!E8 -> 46213.45 | D13: =cleaned_data!H8 -> 22 | E13: =cleaned_data!I8 -> 85.2 | F13: =cleaned_data!G8 -> 0.122 | G13: =cleaned_data!K8 -> 1 | H13: =dummy_variables!E11 -> 0 | I13: =dummy_variables!F11 -> 0 | J13: =dummy_variables!G11 -> 0 | K13: =dummy_variables!H11 -> 0 | L13: =dummy_variables!I11 -> 0 | M13: =dummy_variables!J11 -> 0
A14: 8 | B14: =cleaned_data!F9 -> 8567 | C14: =cleaned_data!E9 -> 68148.52 | D14: =cleaned_data!H9 -> 23 | E14: =cleaned_data!I9 -> 95.6 | F14: =cleaned_data!G9 -> 0.127 | G14: =cleaned_data!K9 -> 0 | H14: =dummy_variables!E12 -> 0 | I14: =dummy_variables!F12 -> 0 | J14: =dummy_variables!G12 -> 0 | K14: =dummy_variables!H12 -> 0 | L14: =dummy_variables!I12 -> 0 | M14: =dummy_variables!J12 -> 0
A15: 9 | B15: =cleaned_data!F10 -> 10979 | C15: =cleaned_data!E10 -> 71838.86 | D15: =cleaned_data!H10 -> 26 | E15: =cleaned_data!I10 -> 88.6 | F15: =cleaned_data!G10 -> 0.215 | G15: =cleaned_data!K10 -> 1 | H15: =dummy_variables!E13 -> 0 | I15: =dummy_variables!F13 -> 0 | J15: =dummy_variables!G13 -> 1 | K15: =dummy_variables!H13 -> 1 | L15: =dummy_variables!I13 -> 0 | M15: =dummy_variables!J13 -> 0
A16: 10 | B16: =cleaned_data!F11 -> 9459 | C16: =cleaned_data!E11 -> 68133.44 | D16: =cleaned_data!H11 -> 21 | E16: =cleaned_data!I11 -> 85 | F16: =cleaned_data!G11 -> 0.22 | G16: =cleaned_data!K11 -> 0 | H16: =dummy_variables!E14 -> 0 | I16: =dummy_variables!F14 -> 0 | J16: =dummy_variables!G14 -> 1 | K16: =dummy_variables!H14 -> 1 | L16: =dummy_variables!I14 -> 0 | M16: =dummy_variables!J14 -> 0
A17: 11 | B17: =cleaned_data!F12 -> 9172 | C17: =cleaned_data!E12 -> 34285.21 | D17: =cleaned_data!H12 -> 22 | E17: =cleaned_data!I12 -> 88.3 | F17: =cleaned_data!G12 -> 0.213 | G17: =cleaned_data!K12 -> 1 | H17: =dummy_variables!E15 -> 0 | I17: =dummy_variables!F15 -> 0 | J17: =dummy_variables!G15 -> 1 | K17: =dummy_variables!H15 -> 1 | L17: =dummy_variables!I15 -> 0 | M17: =dummy_variables!J15 -> 0
A18: 12 | B18: =cleaned_data!F13 -> 11230 | C18: =cleaned_data!E13 -> 67979.88 | D18: =cleaned_data!H13 -> 28 | E18: =cleaned_data!I13 -> 85.3 | F18: =cleaned_data!G13 -> 0.002 | G18: =cleaned_data!K13 -> 0 | H18: =dummy_variables!E16 -> 0 | I18: =dummy_variables!F16 -> 0 | J18: =dummy_variables!G16 -> 1 | K18: =dummy_variables!H16 -> 1 | L18: =dummy_variables!I16 -> 0 | M18: =dummy_variables!J16 -> 0
... A326: 320 | B326: =cleaned_data!F321 -> 5317 | C326: =cleaned_data!E321 -> 40553.11 | D326: =cleaned_data!H321 -> 17 | E326: =cleaned_data!I321 -> 84.3 | F326: =cleaned_data!G321 -> 0.165 | G326: =cleaned_data!K321 -> 0 | H326: =dummy_variables!E324 -> 0 | I326: =dummy_variables!F324 -> 1 | J326: =dummy_variables!G324 -> 0 | K326: =dummy_variables!H324 -> 0 | L326: =dummy_variables!I324 -> 0 | M326: =dummy_variables!J324 -> 0
A329: Regression Results
A330: Variable | B330: Coefficient | C330: Std. Error | D330: t-stat | E330: P-value | F330: Lower 95% | G330: Upper 95%
A331: footfall | B331: =INDEX(LINEST(cleaned_data!M2:M321,B7:M326,TRUE(),TRUE()),1,12) -> 27.991194 | C331: =INDEX(LINEST(cleaned_data!M2:M321,B7:M326,TRUE(),TRUE()),2,12) -> 2.4765581 | D331: =B331/C331 -> 11.302458 | E331: =_xlfn.T.DIST.2T(ABS(D331),307) -> 5.3369487e-25 | F331: =B331-_xlfn.T.INV.2T(0.05,307)*C331 -> 23.118017 | G331: =B331+_xlfn.T.INV.2T(0.05,307)*C331 -> 32.86437
A332: marketing_spend | B332: =INDEX(LINEST(cleaned_data!M2:M321,B7:M326,TRUE(),TRUE()),1,11) -> 1.1545804 | C332: =INDEX(LINEST(cleaned_data!M2:M321,B7:M326,TRUE(),TRUE()),2,11) -> 0.12532441 | D332: =B332/C332 -> 9.2127334 | E332: =_xlfn.T.DIST.2T(ABS(D332),307) -> 5.163462e-18 | F332: =B332-_xlfn.T.INV.2T(0.05,307)*C332 -> 0.90797686 | G332: =B332+_xlfn.T.INV.2T(0.05,307)*C332 -> 1.4011839
A333: staff_count | B333: =INDEX(LINEST(cleaned_data!M2:M321,B7:M326,TRUE(),TRUE()),1,10) -> 3026.302 | C333: =INDEX(LINEST(cleaned_data!M2:M321,B7:M326,TRUE(),TRUE()),2,10) -> 1246.0571 | D333: =B333/C333 -> 2.4287025 | E333: =_xlfn.T.DIST.2T(ABS(D333),307) -> 0.015726923 | F333: =B333-_xlfn.T.INV.2T(0.05,307)*C333 -> 574.40893 | G333: =B333+_xlfn.T.INV.2T(0.05,307)*C333 -> 5478.1951
A334: inventory_availability_pct | B334: =INDEX(LINEST(cleaned_data!M2:M321,B7:M326,TRUE(),TRUE()),1,9) -> 3032.5975 | C334: =INDEX(LINEST(cleaned_data!M2:M321,B7:M326,TRUE(),TRUE()),2,9) -> 456.95481 | D334: =B334/C334 -> 6.6365369 | E334: =_xlfn.T.DIST.2T(ABS(D334),307) -> 1.4530124e-10 | F334: =B334-_xlfn.T.INV.2T(0.05,307)*C334 -> 2133.4378 | G334: =B334+_xlfn.T.INV.2T(0.05,307)*C334 -> 3931.7572
A335: avg_discount_pct | B335: =INDEX(LINEST(cleaned_data!M2:M321,B7:M326,TRUE(),TRUE()),1,8) -> -49804.116 | C335: =INDEX(LINEST(cleaned_data!M2:M321,B7:M326,TRUE(),TRUE()),2,8) -> 36358.08 | D335: =B335/C335 -> -1.3698225 | E335: =_xlfn.T.DIST.2T(ABS(D335),307) -> 0.17174335 | F335: =B335-_xlfn.T.INV.2T(0.05,307)*C335 -> -121346.68 | G335: =B335+_xlfn.T.INV.2T(0.05,307)*C335 -> 21738.453
A336: holiday_flag | B336: =INDEX(LINEST(cleaned_data!M2:M321,B7:M326,TRUE(),TRUE()),1,7) -> 16166.626 | C336: =INDEX(LINEST(cleaned_data!M2:M321,B7:M326,TRUE(),TRUE()),2,7) -> 6565.4317 | D336: =B336/C336 -> 2.4623858 | E336: =_xlfn.T.DIST.2T(ABS(D336),307) -> 0.014350634 | F336: =B336-_xlfn.T.INV.2T(0.05,307)*C336 -> 3247.6862 | G336: =B336+_xlfn.T.INV.2T(0.05,307)*C336 -> 29085.565
A337: store_type_Mall | B337: =INDEX(LINEST(cleaned_data!M2:M321,B7:M326,TRUE(),TRUE()),1,6) -> 11856.483 | C337: =INDEX(LINEST(cleaned_data!M2:M321,B7:M326,TRUE(),TRUE()),2,6) -> 6454.4824 | D337: =B337/C337 -> 1.8369378 | E337: =_xlfn.T.DIST.2T(ABS(D337),307) -> 0.067185628 | F337: =B337-_xlfn.T.INV.2T(0.05,307)*C337 -> -844.13945 | G337: =B337+_xlfn.T.INV.2T(0.05,307)*C337 -> 24557.105
A338: store_type_Residential | B338: =INDEX(LINEST(cleaned_data!M2:M321,B7:M326,TRUE(),TRUE()),1,5) -> -17888.224 | C338: =INDEX(LINEST(cleaned_data!M2:M321,B7:M326,TRUE(),TRUE()),2,5) -> 5954.3798 | D338: =B338/C338 -> -3.0042129 | E338: =_xlfn.T.DIST.2T(ABS(D338),307) -> 0.0028819564 | F338: =B338-_xlfn.T.INV.2T(0.05,307)*C338 -> -29604.784 | G338: =B338+_xlfn.T.INV.2T(0.05,307)*C338 -> -6171.6645
A339: store_type_Airport | B339: =INDEX(LINEST(cleaned_data!M2:M321,B7:M326,TRUE(),TRUE()),1,4) -> 21131.237 | C339: =INDEX(LINEST(cleaned_data!M2:M321,B7:M326,TRUE(),TRUE()),2,4) -> 9237.7578 | D339: =B339/C339 -> 2.2874855 | E339: =_xlfn.T.DIST.2T(ABS(D339),307) -> 0.02284746 | F339: =B339-_xlfn.T.INV.2T(0.05,307)*C339 -> 2953.904 | G339: =B339+_xlfn.T.INV.2T(0.05,307)*C339 -> 39308.569
A340: region_North | B340: =INDEX(LINEST(cleaned_data!M2:M321,B7:M326,TRUE(),TRUE()),1,3) -> 7710.7809 | C340: =INDEX(LINEST(cleaned_data!M2:M321,B7:M326,TRUE(),TRUE()),2,3) -> 6968.3103 | D340: =B340/C340 -> 1.1065496 | E340: =_xlfn.T.DIST.2T(ABS(D340),307) -> 0.26935503 | F340: =B340-_xlfn.T.INV.2T(0.05,307)*C340 -> -6000.9116 | G340: =B340+_xlfn.T.INV.2T(0.05,307)*C340 -> 21422.473
A341: region_South | B341: =INDEX(LINEST(cleaned_data!M2:M321,B7:M326,TRUE(),TRUE()),1,2) -> 19692.487 | C341: =INDEX(LINEST(cleaned_data!M2:M321,B7:M326,TRUE(),TRUE()),2,2) -> 7119.9753 | D341: =B341/C341 -> 2.7658083 | E341: =_xlfn.T.DIST.2T(ABS(D341),307) -> 0.0060221159 | F341: =B341-_xlfn.T.INV.2T(0.05,307)*C341 -> 5682.3597 | G341: =B341+_xlfn.T.INV.2T(0.05,307)*C341 -> 33702.614
A342: region_West | B342: =INDEX(LINEST(cleaned_data!M2:M321,B7:M326,TRUE(),TRUE()),1,1) -> 19831.83 | C342: =INDEX(LINEST(cleaned_data!M2:M321,B7:M326,TRUE(),TRUE()),2,1) -> 6253.492 | D342: =B342/C342 -> 3.1713209 | E342: =_xlfn.T.DIST.2T(ABS(D342),307) -> 0.0016708588 | F342: =B342-_xlfn.T.INV.2T(0.05,307)*C342 -> 7526.7006 | G342: =B342+_xlfn.T.INV.2T(0.05,307)*C342 -> 32136.959
A343: Intercept | B343: =INDEX(LINEST(cleaned_data!M2:M321,B7:M326,TRUE(),TRUE()),1,13) -> 107624.91 | C343: =INDEX(LINEST(cleaned_data!M2:M321,B7:M326,TRUE(),TRUE()),2,13) -> 42939.45 | D343: =B343/C343 -> 2.5064343 | E343: =_xlfn.T.DIST.2T(ABS(D343),307) -> 0.01271242
A345: Model Fit Statistics
A346: R-squared | B346: =INDEX(LINEST(cleaned_data!M2:M321,B7:M326,TRUE(),TRUE()),3,1) -> 0.83374827
A347: Adjusted R-squared | B347: =1-(1-B346)*(320-1)/(320-12-1) -> 0.82724983
A348: Std error of regression | B348: =INDEX(LINEST(cleaned_data!M2:M321,B7:M326,TRUE(),TRUE()),3,2) -> 43130.842
A349: F-statistic | B349: =INDEX(LINEST(cleaned_data!M2:M321,B7:M326,TRUE(),TRUE()),4,1) -> 128.29977
A350: Residual degrees of freedom | B350: =INDEX(LINEST(cleaned_data!M2:M321,B7:M326,TRUE(),TRUE()),4,2) -> 307
A351: N (observations) | B351: =COUNT(B7:B326) -> 320

Sheet predictions_residuals
A1: Predicted Sales and Residuals (Final Multiple Regression Model)
A3: store_id | B3: month | C3: store_type | D3: region | E3: monthly_sales (actual) | F3: predicted_sales | G3: residual
A4: =cleaned_data!A2 -> STR-1001 | B4: =cleaned_data!B2 -> 45658 | C4: =cleaned_data!D2 -> Residential | D4: =cleaned_data!C2 -> East | E4: =cleaned_data!M2 -> 658832.62 | F4: =multiple_regression!B343+multiple_regression!B331*cleaned_data!F2+multiple_regression!B332*cleaned_data!E2+multiple_regression!B333*cleaned_data!H2+multiple_regression!B334*cleaned_data!I2+multiple_regression!B335*cleaned_data!G2+multiple_regression!B336*cleaned_data!K2+multiple_regression!B337*dummy_variables!E5+multiple_regression!B338*dummy_variables!F5+multiple_regression!B339*dummy_variables!G5+multiple_regression!B340*dummy_variables!H5+multiple_regression!B341*dummy_variables!I5+multiple_regression!B342*dummy_variables!J5 -> 696356.26 | G4: =E4-F4 -> -37523.638
A5: =cleaned_data!A3 -> STR-1001 | B5: =cleaned_data!B3 -> 45689 | C5: =cleaned_data!D3 -> Residential | D5: =cleaned_data!C3 -> East | E5: =cleaned_data!M3 -> 634436 | F5: =multiple_regression!B343+multiple_regression!B331*cleaned_data!F3+multiple_regression!B332*cleaned_data!E3+multiple_regression!B333*cleaned_data!H3+multiple_regression!B334*cleaned_data!I3+multiple_regression!B335*cleaned_data!G3+multiple_regression!B336*cleaned_data!K3+multiple_regression!B337*dummy_variables!E6+multiple_regression!B338*dummy_variables!F6+multiple_regression!B339*dummy_variables!G6+multiple_regression!B340*dummy_variables!H6+multiple_regression!B341*dummy_variables!I6+multiple_regression!B342*dummy_variables!J6 -> 695089.85 | G5: =E5-F5 -> -60653.85
A6: =cleaned_data!A4 -> STR-1001 | B6: =cleaned_data!B4 -> 45717 | C6: =cleaned_data!D4 -> Residential | D6: =cleaned_data!C4 -> East | E6: =cleaned_data!M4 -> 678722.06 | F6: =multiple_regression!B343+multiple_regression!B331*cleaned_data!F4+multiple_regression!B332*cleaned_data!E4+multiple_regression!B333*cleaned_data!H4+multiple_regression!B334*cleaned_data!I4+multiple_regression!B335*cleaned_data!G4+multiple_regression!B336*cleaned_data!K4+multiple_regression!B337*dummy_variables!E7+multiple_regression!B338*dummy_variables!F7+multiple_regression!B339*dummy_variables!G7+multiple_regression!B340*dummy_variables!H7+multiple_regression!B341*dummy_variables!I7+multiple_regression!B342*dummy_variables!J7 -> 734775.58 | G6: =E6-F6 -> -56053.521
A7: =cleaned_data!A5 -> STR-1001 | B7: =cleaned_data!B5 -> 45748 | C7: =cleaned_data!D5 -> Residential | D7: =cleaned_data!C5 -> East | E7: =cleaned_data!M5 -> 658920.3 | F7: =multiple_regression!B343+multiple_regression!B331*cleaned_data!F5+multiple_regression!B332*cleaned_data!E5+multiple_regression!B333*cleaned_data!H5+multiple_regression!B334*cleaned_data!I5+multiple_regression!B335*cleaned_data!G5+multiple_regression!B336*cleaned_data!K5+multiple_regression!B337*dummy_variables!E8+multiple_regression!B338*dummy_variables!F8+multiple_regression!B339*dummy_variables!G8+multiple_regression!B340*dummy_variables!H8+multiple_regression!B341*dummy_variables!I8+multiple_regression!B342*dummy_variables!J8 -> 745432.66 | G7: =E7-F7 -> -86512.365
A8: =cleaned_data!A6 -> STR-1002 | B8: =cleaned_data!B6 -> 45658 | C8: =cleaned_data!D6 -> High Street | D8: =cleaned_data!C6 -> East | E8: =cleaned_data!M6 -> 741341.44 | F8: =multiple_regression!B343+multiple_regression!B331*cleaned_data!F6+multiple_regression!B332*cleaned_data!E6+multiple_regression!B333*cleaned_data!H6+multiple_regression!B334*cleaned_data!I6+multiple_regression!B335*cleaned_data!G6+multiple_regression!B336*cleaned_data!K6+multiple_regression!B337*dummy_variables!E9+multiple_regression!B338*dummy_variables!F9+multiple_regression!B339*dummy_variables!G9+multiple_regression!B340*dummy_variables!H9+multiple_regression!B341*dummy_variables!I9+multiple_regression!B342*dummy_variables!J9 -> 794892.87 | G8: =E8-F8 -> -53551.429
A9: =cleaned_data!A7 -> STR-1002 | B9: =cleaned_data!B7 -> 45689 | C9: =cleaned_data!D7 -> High Street | D9: =cleaned_data!C7 -> East | E9: =cleaned_data!M7 -> 761835.34 | F9: =multiple_regression!B343+multiple_regression!B331*cleaned_data!F7+multiple_regression!B332*cleaned_data!E7+multiple_regression!B333*cleaned_data!H7+multiple_regression!B334*cleaned_data!I7+multiple_regression!B335*cleaned_data!G7+multiple_regression!B336*cleaned_data!K7+multiple_regression!B337*dummy_variables!E10+multiple_regression!B338*dummy_variables!F10+multiple_regression!B339*dummy_variables!G10+multiple_regression!B340*dummy_variables!H10+multiple_regression!B341*dummy_variables!I10+multiple_regression!B342*dummy_variables!J10 -> 766837.12 | G9: =E9-F9 -> -5001.7762
A10: =cleaned_data!A8 -> STR-1002 | B10: =cleaned_data!B8 -> 45717 | C10: =cleaned_data!D8 -> High Street | D10: =cleaned_data!C8 -> East | E10: =cleaned_data!M8 -> 806615.54 | F10: =multiple_regression!B343+multiple_regression!B331*cleaned_data!F8+multiple_regression!B332*cleaned_data!E8+multiple_regression!B333*cleaned_data!H8+multiple_regression!B334*cleaned_data!I8+multiple_regression!B335*cleaned_data!G8+multiple_regression!B336*cleaned_data!K8+multiple_regression!B337*dummy_variables!E11+multiple_regression!B338*dummy_variables!F11+multiple_regression!B339*dummy_variables!G11+multiple_regression!B340*dummy_variables!H11+multiple_regression!B341*dummy_variables!I11+multiple_regression!B342*dummy_variables!J11 -> 793183.04 | G10: =E10-F10 -> 13432.503
A11: =cleaned_data!A9 -> STR-1002 | B11: =cleaned_data!B9 -> 45748 | C11: =cleaned_data!D9 -> High Street | D11: =cleaned_data!C9 -> East | E11: =cleaned_data!M9 -> 850164.26 | F11: =multiple_regression!B343+multiple_regression!B331*cleaned_data!F9+multiple_regression!B332*cleaned_data!E9+multiple_regression!B333*cleaned_data!H9+multiple_regression!B334*cleaned_data!I9+multiple_regression!B335*cleaned_data!G9+multiple_regression!B336*cleaned_data!K9+multiple_regression!B337*dummy_variables!E12+multiple_regression!B338*dummy_variables!F12+multiple_regression!B339*dummy_variables!G12+multiple_regression!B340*dummy_variables!H12+multiple_regression!B341*dummy_variables!I12+multiple_regression!B342*dummy_variables!J12 -> 779304.55 | G11: =E11-F11 -> 70859.708
A12: =cleaned_data!A10 -> STR-1003 | B12: =cleaned_data!B10 -> 45658 | C12: =cleaned_data!D10 -> Airport | D12: =cleaned_data!C10 -> North | E12: =cleaned_data!M10 -> 930581.7 | F12: =multiple_regression!B343+multiple_regression!B331*cleaned_data!F10+multiple_regression!B332*cleaned_data!E10+multiple_regression!B333*cleaned_data!H10+multiple_regression!B334*cleaned_data!I10+multiple_regression!B335*cleaned_data!G10+multiple_regression!B336*cleaned_data!K10+multiple_regression!B337*dummy_variables!E13+multiple_regression!B338*dummy_variables!F13+multiple_regression!B339*dummy_variables!G13+multiple_regression!B340*dummy_variables!H13+multiple_regression!B341*dummy_variables!I13+multiple_regression!B342*dummy_variables!J13 -> 879556.71 | G12: =E12-F12 -> 51024.99
A13: =cleaned_data!A11 -> STR-1003 | B13: =cleaned_data!B11 -> 45689 | C13: =cleaned_data!D11 -> Airport | D13: =cleaned_data!C11 -> North | E13: =cleaned_data!M11 -> 779010.94 | F13: =multiple_regression!B343+multiple_regression!B331*cleaned_data!F11+multiple_regression!B332*cleaned_data!E11+multiple_regression!B333*cleaned_data!H11+multiple_regression!B334*cleaned_data!I11+multiple_regression!B335*cleaned_data!G11+multiple_regression!B336*cleaned_data!K11+multiple_regression!B337*dummy_variables!E14+multiple_regression!B338*dummy_variables!F14+multiple_regression!B339*dummy_variables!G14+multiple_regression!B340*dummy_variables!H14+multiple_regression!B341*dummy_variables!I14+multiple_regression!B342*dummy_variables!J14 -> 790267.38 | G13: =E13-F13 -> -11256.443
A14: =cleaned_data!A12 -> STR-1003 | B14: =cleaned_data!B12 -> 45717 | C14: =cleaned_data!D12 -> Airport | D14: =cleaned_data!C12 -> North | E14: =cleaned_data!M12 -> 723060.76 | F14: =multiple_regression!B343+multiple_regression!B331*cleaned_data!F12+multiple_regression!B332*cleaned_data!E12+multiple_regression!B333*cleaned_data!H12+multiple_regression!B334*cleaned_data!I12+multiple_regression!B335*cleaned_data!G12+multiple_regression!B336*cleaned_data!K12+multiple_regression!B337*dummy_variables!E15+multiple_regression!B338*dummy_variables!F15+multiple_regression!B339*dummy_variables!G15+multiple_regression!B340*dummy_variables!H15+multiple_regression!B341*dummy_variables!I15+multiple_regression!B342*dummy_variables!J15 -> 772702.54 | G14: =E14-F14 -> -49641.777
A15: =cleaned_data!A13 -> STR-1003 | B15: =cleaned_data!B13 -> 45748 | C15: =cleaned_data!D13 -> Airport | D15: =cleaned_data!C13 -> North | E15: =cleaned_data!M13 -> 910791.94 | F15: =multiple_regression!B343+multiple_regression!B331*cleaned_data!F13+multiple_regression!B332*cleaned_data!E13+multiple_regression!B333*cleaned_data!H13+multiple_regression!B334*cleaned_data!I13+multiple_regression!B335*cleaned_data!G13+multiple_regression!B336*cleaned_data!K13+multiple_regression!B337*dummy_variables!E16+multiple_regression!B338*dummy_variables!F16+multiple_regression!B339*dummy_variables!G16+multiple_regression!B340*dummy_variables!H16+multiple_regression!B341*dummy_variables!I16+multiple_regression!B342*dummy_variables!J16 -> 872613.68 | G15: =E15-F15 -> 38178.26
A16: =cleaned_data!A14 -> STR-1004 | B16: =cleaned_data!B14 -> 45658 | C16: =cleaned_data!D14 -> Residential | D16: =cleaned_data!C14 -> East | E16: =cleaned_data!M14 -> 922168.6 | F16: =multiple_regression!B343+multiple_regression!B331*cleaned_data!F14+multiple_regression!B332*cleaned_data!E14+multiple_regression!B333*cleaned_data!H14+multiple_regression!B334*cleaned_data!I14+multiple_regression!B335*cleaned_data!G14+multiple_regression!B336*cleaned_data!K14+multiple_regression!B337*dummy_variables!E17+multiple_regression!B338*dummy_variables!F17+multiple_regression!B339*dummy_variables!G17+multiple_regression!B340*dummy_variables!H17+multiple_regression!B341*dummy_variables!I17+multiple_regression!B342*dummy_variables!J17 -> 879197.31 | G16: =E16-F16 -> 42971.294
A17: =cleaned_data!A15 -> STR-1004 | B17: =cleaned_data!B15 -> 45689 | C17: =cleaned_data!D15 -> Residential | D17: =cleaned_data!C15 -> East | E17: =cleaned_data!M15 -> 726606.28 | F17: =multiple_regression!B343+multiple_regression!B331*cleaned_data!F15+multiple_regression!B332*cleaned_data!E15+multiple_regression!B333*cleaned_data!H15+multiple_regression!B334*cleaned_data!I15+multiple_regression!B335*cleaned_data!G15+multiple_regression!B336*cleaned_data!K15+multiple_regression!B337*dummy_variables!E18+multiple_regression!B338*dummy_variables!F18+multiple_regression!B339*dummy_variables!G18+multiple_regression!B340*dummy_variables!H18+multiple_regression!B341*dummy_variables!I18+multiple_regression!B342*dummy_variables!J18 -> 758317.07 | G17: =E17-F17 -> -31710.787
A18: =cleaned_data!A16 -> STR-1004 | B18: =cleaned_data!B16 -> 45717 | C18: =cleaned_data!D16 -> Residential | D18: =cleaned_data!C16 -> East | E18: =cleaned_data!M16 -> 746501.09 | F18: =multiple_regression!B343+multiple_regression!B331*cleaned_data!F16+multiple_regression!B332*cleaned_data!E16+multiple_regression!B333*cleaned_data!H16+multiple_regression!B334*cleaned_data!I16+multiple_regression!B335*cleaned_data!G16+multiple_regression!B336*cleaned_data!K16+multiple_regression!B337*dummy_variables!E19+multiple_regression!B338*dummy_variables!F19+multiple_regression!B339*dummy_variables!G19+multiple_regression!B340*dummy_variables!H19+multiple_regression!B341*dummy_variables!I19+multiple_regression!B342*dummy_variables!J19 -> 735432.96 | G18: =E18-F18 -> 11068.128
A19: =cleaned_data!A17 -> STR-1004 | B19: =cleaned_data!B17 -> 45748 | C19: =cleaned_data!D17 -> Residential | D19: =cleaned_data!C17 -> East | E19: =cleaned_data!M17 -> 834017.02 | F19: =multiple_regression!B343+multiple_regression!B331*cleaned_data!F17+multiple_regression!B332*cleaned_data!E17+multiple_regression!B333*cleaned_data!H17+multiple_regression!B334*cleaned_data!I17+multiple_regression!B335*cleaned_data!G17+multiple_regression!B336*cleaned_data!K17+multiple_regression!B337*dummy_variables!E20+multiple_regression!B338*dummy_variables!F20+multiple_regression!B339*dummy_variables!G20+multiple_regression!B340*dummy_variables!H20+multiple_regression!B341*dummy_variables!I20+multiple_regression!B342*dummy_variables!J20 -> 793285.57 | G19: =E19-F19 -> 40731.446
A20: =cleaned_data!A18 -> STR-1005 | B20: =cleaned_data!B18 -> 45658 | C20: =cleaned_data!D18 -> Residential | D20: =cleaned_data!C18 -> South | E20: =cleaned_data!M18 -> 666152.52 | F20: =multiple_regression!B343+multiple_regression!B331*cleaned_data!F18+multiple_regression!B332*cleaned_data!E18+multiple_regression!B333*cleaned_data!H18+multiple_regression!B334*cleaned_data!I18+multiple_regression!B335*cleaned_data!G18+multiple_regression!B336*cleaned_data!K18+multiple_regression!B337*dummy_variables!E21+multiple_regression!B338*dummy_variables!F21+multiple_regression!B339*dummy_variables!G21+multiple_regression!B340*dummy_variables!H21+multiple_regression!B341*dummy_variables!I21+multiple_regression!B342*dummy_variables!J21 -> 674415.73 | G20: =E20-F20 -> -8263.2092
A21: =cleaned_data!A19 -> STR-1005 | B21: =cleaned_data!B19 -> 45689 | C21: =cleaned_data!D19 -> Residential | D21: =cleaned_data!C19 -> South | E21: =cleaned_data!M19 -> 573155.19 | F21: =multiple_regression!B343+multiple_regression!B331*cleaned_data!F19+multiple_regression!B332*cleaned_data!E19+multiple_regression!B333*cleaned_data!H19+multiple_regression!B334*cleaned_data!I19+multiple_regression!B335*cleaned_data!G19+multiple_regression!B336*cleaned_data!K19+multiple_regression!B337*dummy_variables!E22+multiple_regression!B338*dummy_variables!F22+multiple_regression!B339*dummy_variables!G22+multiple_regression!B340*dummy_variables!H22+multiple_regression!B341*dummy_variables!I22+multiple_regression!B342*dummy_variables!J22 -> 583977.57 | G21: =E21-F21 -> -10822.376
A22: =cleaned_data!A20 -> STR-1005 | B22: =cleaned_data!B20 -> 45717 | C22: =cleaned_data!D20 -> Residential | D22: =cleaned_data!C20 -> South | E22: =cleaned_data!M20 -> 666573.2 | F22: =multiple_regression!B343+multiple_regression!B331*cleaned_data!F20+multiple_regression!B332*cleaned_data!E20+multiple_regression!B333*cleaned_data!H20+multiple_regression!B334*cleaned_data!I20+multiple_regression!B335*cleaned_data!G20+multiple_regression!B336*cleaned_data!K20+multiple_regression!B337*dummy_variables!E23+multiple_regression!B338*dummy_variables!F23+multiple_regression!B339*dummy_variables!G23+multiple_regression!B340*dummy_variables!H23+multiple_regression!B341*dummy_variables!I23+multiple_regression!B342*dummy_variables!J23 -> 686223.22 | G22: =E22-F22 -> -19650.02
A23: =cleaned_data!A21 -> STR-1005 | B23: =cleaned_data!B21 -> 45748 | C23: =cleaned_data!D21 -> Residential | D23: =cleaned_data!C21 -> South | E23: =cleaned_data!M21 -> 591619.95 | F23: =multiple_regression!B343+multiple_regression!B331*cleaned_data!F21+multiple_regression!B332*cleaned_data!E21+multiple_regression!B333*cleaned_data!H21+multiple_regression!B334*cleaned_data!I21+multiple_regression!B335*cleaned_data!G21+multiple_regression!B336*cleaned_data!K21+multiple_regression!B337*dummy_variables!E24+multiple_regression!B338*dummy_variables!F24+multiple_regression!B339*dummy_variables!G24+multiple_regression!B340*dummy_variables!H24+multiple_regression!B341*dummy_variables!I24+multiple_regression!B342*dummy_variables!J24 -> 601784.51 | G23: =E23-F23 -> -10164.558
A24: =cleaned_data!A22 -> STR-1006 | B24: =cleaned_data!B22 -> 45658 | C24: =cleaned_data!D22 -> Residential | D24: =cleaned_data!C22 -> North | E24: =cleaned_data!M22 -> 415721.82 | F24: =multiple_regression!B343+multiple_regression!B331*cleaned_data!F22+multiple_regression!B332*cleaned_data!E22+multiple_regression!B333*cleaned_data!H22+multiple_regression!B334*cleaned_data!I22+multiple_regression!B335*cleaned_data!G22+multiple_regression!B336*cleaned_data!K22+multiple_regression!B337*dummy_variables!E25+multiple_regression!B338*dummy_variables!F25+multiple_regression!B339*dummy_variables!G25+multiple_regression!B340*dummy_variables!H25+multiple_regression!B341*dummy_variables!I25+multiple_regression!B342*dummy_variables!J25 -> 484383.61 | G24: =E24-F24 -> -68661.794
A25: =cleaned_data!A23 -> STR-1006 | B25: =cleaned_data!B23 -> 45689 | C25: =cleaned_data!D23 -> Residential | D25: =cleaned_data!C23 -> North | E25: =cleaned_data!M23 -> 491905.13 | F25: =multiple_regression!B343+multiple_regression!B331*cleaned_data!F23+multiple_regression!B332*cleaned_data!E23+multiple_regression!B333*cleaned_data!H23+multiple_regression!B334*cleaned_data!I23+multiple_regression!B335*cleaned_data!G23+multiple_regression!B336*cleaned_data!K23+multiple_regression!B337*dummy_variables!E26+multiple_regression!B338*dummy_variables!F26+multiple_regression!B339*dummy_variables!G26+multiple_regression!B340*dummy_variables!H26+multiple_regression!B341*dummy_variables!I26+multiple_regression!B342*dummy_variables!J26 -> 479346.8 | G25: =E25-F25 -> 12558.331
A26: =cleaned_data!A24 -> STR-1006 | B26: =cleaned_data!B24 -> 45717 | C26: =cleaned_data!D24 -> Residential | D26: =cleaned_data!C24 -> North | E26: =cleaned_data!M24 -> 555929.4 | F26: =multiple_regression!B343+multiple_regression!B331*cleaned_data!F24+multiple_regression!B332*cleaned_data!E24+multiple_regression!B333*cleaned_data!H24+multiple_regression!B334*cleaned_data!I24+multiple_regression!B335*cleaned_data!G24+multiple_regression!B336*cleaned_data!K24+multiple_regression!B337*dummy_variables!E27+multiple_regression!B338*dummy_variables!F27+multiple_regression!B339*dummy_variables!G27+multiple_regression!B340*dummy_variables!H27+multiple_regression!B341*dummy_variables!I27+multiple_regression!B342*dummy_variables!J27 -> 536623.81 | G26: =E26-F26 -> 19305.595
A27: =cleaned_data!A25 -> STR-1006 | B27: =cleaned_data!B25 -> 45748 | C27: =cleaned_data!D25 -> Residential | D27: =cleaned_data!C25 -> North | E27: =cleaned_data!M25 -> 565810.99 | F27: =multiple_regression!B343+multiple_regression!B331*cleaned_data!F25+multiple_regression!B332*cleaned_data!E25+multiple_regression!B333*cleaned_data!H25+multiple_regression!B334*cleaned_data!I25+multiple_regression!B335*cleaned_data!G25+multiple_regression!B336*cleaned_data!K25+multiple_regression!B337*dummy_variables!E28+multiple_regression!B338*dummy_variables!F28+multiple_regression!B339*dummy_variables!G28+multiple_regression!B340*dummy_variables!H28+multiple_regression!B341*dummy_variables!I28+multiple_regression!B342*dummy_variables!J28 -> 547102.37 | G27: =E27-F27 -> 18708.617
A28: =cleaned_data!A26 -> STR-1007 | B28: =cleaned_data!B26 -> 45658 | C28: =cleaned_data!D26 -> Mall | D28: =cleaned_data!C26 -> West | E28: =cleaned_data!M26 -> 811771.14 | F28: =multiple_regression!B343+multiple_regression!B331*cleaned_data!F26+multiple_regression!B332*cleaned_data!E26+multiple_regression!B333*cleaned_data!H26+multiple_regression!B334*cleaned_data!I26+multiple_regression!B335*cleaned_data!G26+multiple_regression!B336*cleaned_data!K26+multiple_regression!B337*dummy_variables!E29+multiple_regression!B338*dummy_variables!F29+multiple_regression!B339*dummy_variables!G29+multiple_regression!B340*dummy_variables!H29+multiple_regression!B341*dummy_variables!I29+multiple_regression!B342*dummy_variables!J29 -> 849064.2 | G28: =E28-F28 -> -37293.059
A29: =cleaned_data!A27 -> STR-1007 | B29: =cleaned_data!B27 -> 45689 | C29: =cleaned_data!D27 -> Mall | D29: =cleaned_data!C27 -> West | E29: =cleaned_data!M27 -> 800451.94 | F29: =multiple_regression!B343+multiple_regression!B331*cleaned_data!F27+multiple_regression!B332*cleaned_data!E27+multiple_regression!B333*cleaned_data!H27+multiple_regression!B334*cleaned_data!I27+multiple_regression!B335*cleaned_data!G27+multiple_regression!B336*cleaned_data!K27+multiple_regression!B337*dummy_variables!E30+multiple_regression!B338*dummy_variables!F30+multiple_regression!B339*dummy_variables!G30+multiple_regression!B340*dummy_variables!H30+multiple_regression!B341*dummy_variables!I30+multiple_regression!B342*dummy_variables!J30 -> 909274.15 | G29: =E29-F29 -> -108822.21
A30: =cleaned_data!A28 -> STR-1007 | B30: =cleaned_data!B28 -> 45717 | C30: =cleaned_data!D28 -> Mall | D30: =cleaned_data!C28 -> West | E30: =cleaned_data!M28 -> 783672.82 | F30: =multiple_regression!B343+multiple_regression!B331*cleaned_data!F28+multiple_regression!B332*cleaned_data!E28+multiple_regression!B333*cleaned_data!H28+multiple_regression!B334*cleaned_data!I28+multiple_regression!B335*cleaned_data!G28+multiple_regression!B336*cleaned_data!K28+multiple_regression!B337*dummy_variables!E31+multiple_regression!B338*dummy_variables!F31+multiple_regression!B339*dummy_variables!G31+multiple_regression!B340*dummy_variables!H31+multiple_regression!B341*dummy_variables!I31+multiple_regression!B342*dummy_variables!J31 -> 803749.21 | G30: =E30-F30 -> -20076.388
A31: =cleaned_data!A29 -> STR-1007 | B31: =cleaned_data!B29 -> 45748 | C31: =cleaned_data!D29 -> Mall | D31: =cleaned_data!C29 -> West | E31: =cleaned_data!M29 -> 701641.97 | F31: =multiple_regression!B343+multiple_regression!B331*cleaned_data!F29+multiple_regression!B332*cleaned_data!E29+multiple_regression!B333*cleaned_data!H29+multiple_regression!B334*cleaned_data!I29+multiple_regression!B335*cleaned_data!G29+multiple_regression!B336*cleaned_data!K29+multiple_regression!B337*dummy_variables!E32+multiple_regression!B338*dummy_variables!F32+multiple_regression!B339*dummy_variables!G32+multiple_regression!B340*dummy_variables!H32+multiple_regression!B341*dummy_variables!I32+multiple_regression!B342*dummy_variables!J32 -> 700046.87 | G31: =E31-F31 -> 1595.0975
A32: =cleaned_data!A30 -> STR-1008 | B32: =cleaned_data!B30 -> 45658 | C32: =cleaned_data!D30 -> Residential | D32: =cleaned_data!C30 -> East | E32: =cleaned_data!M30 -> 511844.41 | F32: =multiple_regression!B343+multiple_regression!B331*cleaned_data!F30+multiple_regression!B332*cleaned_data!E30+multiple_regression!B333*cleaned_data!H30+multiple_regression!B334*cleaned_data!I30+multiple_regression!B335*cleaned_data!G30+multiple_regression!B336*cleaned_data!K30+multiple_regression!B337*dummy_variables!E33+multiple_regression!B338*dummy_variables!F33+multiple_regression!B339*dummy_variables!G33+multiple_regression!B340*dummy_variables!H33+multiple_regression!B341*dummy_variables!I33+multiple_regression!B342*dummy_variables!J33 -> 565454.89 | G32: =E32-F32 -> -53610.483
A33: =cleaned_data!A31 -> STR-1008 | B33: =cleaned_data!B31 -> 45689 | C33: =cleaned_data!D31 -> Residential | D33: =cleaned_data!C31 -> East | E33: =cleaned_data!M31 -> 537383.79 | F33: =multiple_regression!B343+multiple_regression!B331*cleaned_data!F31+multiple_regression!B332*cleaned_data!E31+multiple_regression!B333*cleaned_data!H31+multiple_regression!B334*cleaned_data!I31+multiple_regression!B335*cleaned_data!G31+multiple_regression!B336*cleaned_data!K31+multiple_regression!B337*dummy_variables!E34+multiple_regression!B338*dummy_variables!F34+multiple_regression!B339*dummy_variables!G34+multiple_regression!B340*dummy_variables!H34+multiple_regression!B341*dummy_variables!I34+multiple_regression!B342*dummy_variables!J34 -> 511409.56 | G33: =E33-F33 -> 25974.23
A34: =cleaned_data!A32 -> STR-1008 | B34: =cleaned_data!B32 -> 45717 | C34: =cleaned_data!D32 -> Residential | D34: =cleaned_data!C32 -> East | E34: =cleaned_data!M32 -> 500173.02 | F34: =multiple_regression!B343+multiple_regression!B331*cleaned_data!F32+multiple_regression!B332*cleaned_data!E32+multiple_regression!B333*cleaned_data!H32+multiple_regression!B334*cleaned_data!I32+multiple_regression!B335*cleaned_data!G32+multiple_regression!B336*cleaned_data!K32+multiple_regression!B337*dummy_variables!E35+multiple_regression!B338*dummy_variables!F35+multiple_regression!B339*dummy_variables!G35+multiple_regression!B340*dummy_variables!H35+multiple_regression!B341*dummy_variables!I35+multiple_regression!B342*dummy_variables!J35 -> 519162.62 | G34: =E34-F34 -> -18989.605
